Namespace(layers=[0, 1, 2, 3, 4, 5, 6, 7, 8, 9, 10, 11, 12, 13, 14, 15, 16, 17, 18, 19, 20, 21, 22, 23, 24, 25, 26, 27, 28, 29, 30, 31, 32, 33, 34, 35, 36, 37, 38, 39, 40, 41], save_activations=True, data_path='./data_for_STA/data', data_name='politically-liberal', mode='personality', data_type='personality', model_name='gemma-2-9b-it', system_prompt='', model_name_or_path='./model/gemma-2-9b-it', AB=False)
Traceback (most recent call last):
  File "/home/skabi9001/anaconda3/lib/python3.12/site-packages/transformers/utils/hub.py", line 424, in cached_files
    hf_hub_download(
  File "/home/skabi9001/anaconda3/lib/python3.12/site-packages/huggingface_hub/utils/_validators.py", line 106, in _inner_fn
    validate_repo_id(arg_value)
  File "/home/skabi9001/anaconda3/lib/python3.12/site-packages/huggingface_hub/utils/_validators.py", line 154, in validate_repo_id
    raise HFValidationError(
huggingface_hub.errors.HFValidationError: Repo id must be in the form 'repo_name' or 'namespace/repo_name': './model/gemma-2-9b-it'. Use `repo_type` argument if needed.

During handling of the above exception, another exception occurred:

Traceback (most recent call last):
  File "/home/skabi9001/activation_steering/llm-ideological-depth/./baseline/generate_vectors.py", line 68, in <module>
    GemmaWrapper(args.model_name_or_path)
  File "/home/skabi9001/activation_steering/llm-ideological-depth/baseline/model_wrapper.py", line 315, in __init__
    self.tokenizer = AutoTokenizer.from_pretrained(
                     ^^^^^^^^^^^^^^^^^^^^^^^^^^^^^^
  File "/home/skabi9001/anaconda3/lib/python3.12/site-packages/transformers/models/auto/tokenization_auto.py", line 945, in from_pretrained
    tokenizer_config = get_tokenizer_config(pretrained_model_name_or_path, **kwargs)
                       ^^^^^^^^^^^^^^^^^^^^^^^^^^^^^^^^^^^^^^^^^^^^^^^^^^^^^^^^^^^^^
  File "/home/skabi9001/anaconda3/lib/python3.12/site-packages/transformers/models/auto/tokenization_auto.py", line 777, in get_tokenizer_config
    resolved_config_file = cached_file(
                           ^^^^^^^^^^^^
  File "/home/skabi9001/anaconda3/lib/python3.12/site-packages/transformers/utils/hub.py", line 266, in cached_file
    file = cached_files(path_or_repo_id=path_or_repo_id, filenames=[filename], **kwargs)
           ^^^^^^^^^^^^^^^^^^^^^^^^^^^^^^^^^^^^^^^^^^^^^^^^^^^^^^^^^^^^^^^^^^^^^^^^^^^^^
  File "/home/skabi9001/anaconda3/lib/python3.12/site-packages/transformers/utils/hub.py", line 471, in cached_files
    _get_cache_file_to_return(path_or_repo_id, filename, cache_dir, revision) for filename in full_filenames
    ^^^^^^^^^^^^^^^^^^^^^^^^^^^^^^^^^^^^^^^^^^^^^^^^^^^^^^^^^^^^^^^^^^^^^^^^^
  File "/home/skabi9001/anaconda3/lib/python3.12/site-packages/transformers/utils/hub.py", line 134, in _get_cache_file_to_return
    resolved_file = try_to_load_from_cache(path_or_repo_id, full_filename, cache_dir=cache_dir, revision=revision)
                    ^^^^^^^^^^^^^^^^^^^^^^^^^^^^^^^^^^^^^^^^^^^^^^^^^^^^^^^^^^^^^^^^^^^^^^^^^^^^^^^^^^^^^^^^^^^^^^
  File "/home/skabi9001/anaconda3/lib/python3.12/site-packages/huggingface_hub/utils/_validators.py", line 106, in _inner_fn
    validate_repo_id(arg_value)
  File "/home/skabi9001/anaconda3/lib/python3.12/site-packages/huggingface_hub/utils/_validators.py", line 154, in validate_repo_id
    raise HFValidationError(
huggingface_hub.errors.HFValidationError: Repo id must be in the form 'repo_name' or 'namespace/repo_name': './model/gemma-2-9b-it'. Use `repo_type` argument if needed.
